<?xml version="1.0" ?>
<robot name="finalrobot2_1100452" xmlns:xacro="http://www.ros.org/wiki/xacro" >
  <!-- ダミーリンクを追加 -->
  <link name="dummy_link"/>

  <!-- ダミージョイントを追加 -->
  <joint name="dummy_joint" type="fixed">
    <parent link="dummy_link"/>
    <child link="base_link"/>
    <origin xyz="0 0 0" rpy="0 0 0"/>
  </joint>

  
  <!-- ベースリンクの定義 -->
  <link name="base_link">
    <visual>
      <geometry>
        <mesh filename="package://finalrobot2_1100452_description/meshes/base_link.stl"/>
      </geometry>
      <material name="grey">
        <color rgba="0.8 0.8 0.8 1.0"/>
      </material>
    </visual>
    <collision>
      <geometry>
        <mesh filename="package://finalrobot2_1100452_description/meshes/base_link.stl"/>
      </geometry>
    </collision>
    <inertial>
      <mass value="1.0"/>
      <origin xyz="0 0 0" rpy="0 0 0"/>
      <inertia ixx="1.0" ixy="0.0" ixz="0.0" iyy="1.0" iyz="0.0" izz="1.0"/>
    </inertial>
  </link>

  <!-- 左車輪の定義 -->
  <link name="left_wheel_1">
    <visual>
      <geometry>
        <mesh filename="package://finalrobot2_1100452_description/meshes/left_wheel_1.stl"/>
      </geometry>
      <material name="red">
        <color rgba="0.8 0.1 0.1 1.0"/>
      </material>
    </visual>
    <collision>
      <geometry>
        <mesh filename="package://finalrobot2_1100452_description/meshes/left_wheel_1.stl"/>
      </geometry>
    </collision>
    <inertial>
      <mass value="1.0"/>
      <origin xyz="0 0 0" rpy="0 0 0"/>
      <inertia ixx="1.0" ixy="0.0" ixz="0.0" iyy="1.0" iyz="0.0" izz="1.0"/>
    </inertial>
  </link>

  <!-- 右車輪の定義 -->
  <link name="right_wheel_1">
    <visual>
      <geometry>
        <mesh filename="package://finalrobot2_1100452_description/meshes/right_wheel_1.stl"/>
      </geometry>
      <material name="green">
        <color rgba="0.1 0.8 0.1 1.0"/>
      </material>
    </visual>
    <collision>
      <geometry>
        <mesh filename="package://finalrobot2_1100452_description/meshes/right_wheel_1.stl"/>
      </geometry>
    </collision>
    <inertial>
      <mass value="1.0"/>
      <origin xyz="0 0 0" rpy="0 0 0"/>
      <inertia ixx="1.0" ixy="0.0" ixz="0.0" iyy="1.0" iyz="0.0" izz="1.0"/>
    </inertial>
  </link>

  <!-- Lidarリンクの定義 -->
  <link name="lidar_1">
    <visual>
      <geometry>
        <mesh filename="package://finalrobot2_1100452_description/meshes/lidar_1.stl"/>
      </geometry>
      <material name="blue">
        <color rgba="0.1 0.1 0.8 1.0"/>
      </material>
    </visual>
    <collision>
      <geometry>
        <mesh filename="package://finalrobot2_1100452_description/meshes/lidar_1.stl"/>
      </geometry>
    </collision>
    <inertial>
      <mass value="0.1"/>
      <origin xyz="0 0 0" rpy="0 0 0"/>
      <inertia ixx="0.1" ixy="0.0" ixz="0.0" iyy="0.1" iyz="0.0" izz="0.1"/>
    </inertial>
  </link>

  <!-- ジョイントの定義 -->
  <joint name="left_wheel_joint" type="revolute">
    <parent link="base_link"/>
    <child link="left_wheel_1"/>
    <origin xyz="-0.5 0.5 0" rpy="0 0 0"/>
    <axis xyz="0 1 0"/>
    <limit effort="1000" lower="-3.14" upper="3.14" velocity="1.0"/>
  </joint>

  <joint name="right_wheel_joint" type="revolute">
    <parent link="base_link"/>
    <child link="right_wheel_1"/>
    <origin xyz="0.5 0.5 0" rpy="0 0 0"/>
    <axis xyz="0 1 0"/>
    <limit effort="1000" lower="-3.14" upper="3.14" velocity="1.0"/>
  </joint>

  <joint name="lidar_joint" type="fixed">
    <parent link="base_link"/>
    <child link="lidar_1"/>
    <origin xyz="0 0 1" rpy="0 0 0"/>
  </joint>

  <!-- トランスミッションの定義 -->
  <transmission name="left_wheel_trans">
    <type>transmission_interface/SimpleTransmission</type>
    <joint name="left_wheel_joint">
      <hardwareInterface>hardware_interface/EffortJointInterface</hardwareInterface>
    </joint>
    <actuator name="left_wheel_motor">
      <hardwareInterface>hardware_interface/EffortJointInterface</hardwareInterface>
      <mechanicalReduction>1</mechanicalReduction>
    </actuator>
  </transmission>

  <transmission name="right_wheel_trans">
    <type>transmission_interface/SimpleTransmission</type>
    <joint name="right_wheel_joint">
      <hardwareInterface>hardware_interface/EffortJointInterface</hardwareInterface>
    </joint>
    <actuator name="right_wheel_motor">
      <hardwareInterface>hardware_interface/EffortJointInterface</hardwareInterface>
      <mechanicalReduction>1</mechanicalReduction>
    </actuator>
  </transmission>

</robot>

