<?xml version="1.0" ?>
<robot name="finalrobot2_1100452" xmlns:xacro="http://www.ros.org/wiki/xacro">

<xacro:include filename="$(find finalrobot2_1100452_description)/urdf/materials.xacro" />
<xacro:include filename="$(find finalrobot2_1100452_description)/urdf/finalrobot2_1100452.trans" />
<xacro:include filename="$(find finalrobot2_1100452_description)/urdf/finalrobot2_1100452.gazebo" />
<link name="base_link">
  <inertial>
    <origin xyz="0.0002900038759478602 -0.004096946178674347 0.027262896271212162" rpy="0 0 0"/>
    <mass value="3.3835754670272715"/>
    <inertia ixx="0.005751" iyy="0.004553" izz="0.009591" ixy="-4e-06" iyz="0.000313" ixz="2e-06"/>
  </inertial>
  <visual>
    <origin xyz="0 0 0" rpy="0 0 0"/>
    <geometry>
      <mesh filename="package://finalrobot2_1100452_description/meshes/base_link.stl" scale="0.001 0.001 0.001"/>
    </geometry>
    <material name="silver"/>
  </visual>
  <collision>
    <origin xyz="0 0 0" rpy="0 0 0"/>
    <geometry>
      <mesh filename="package://finalrobot2_1100452_description/meshes/base_link.stl" scale="0.001 0.001 0.001"/>
    </geometry>
  </collision>
</link>

<link name="right_wheel_1">
  <inertial>
    <origin xyz="0.010000000000000002 -3.618764437576268e-18 -6.938893903907228e-18" rpy="0 0 0"/>
    <mass value="0.3082687791334984"/>
    <inertia ixx="9.6e-05" iyy="5.8e-05" izz="5.8e-05" ixy="-0.0" iyz="-0.0" ixz="0.0"/>
  </inertial>
  <visual>
    <origin xyz="-0.03 -0.0 -0.025" rpy="0 0 0"/>
    <geometry>
      <mesh filename="package://finalrobot2_1100452_description/meshes/right_wheel_1.stl" scale="0.001 0.001 0.001"/>
    </geometry>
    <material name="silver"/>
  </visual>
  <collision>
    <origin xyz="-0.03 -0.0 -0.025" rpy="0 0 0"/>
    <geometry>
      <mesh filename="package://finalrobot2_1100452_description/meshes/right_wheel_1.stl" scale="0.001 0.001 0.001"/>
    </geometry>
  </collision>
</link>

<link name="left_wheel_1">
  <inertial>
    <origin xyz="-0.009999999999999995 -3.618764437576268e-18 -6.938893903907228e-18" rpy="0 0 0"/>
    <mass value="0.3082687791334984"/>
    <inertia ixx="9.6e-05" iyy="5.8e-05" izz="5.8e-05" ixy="-0.0" iyz="-0.0" ixz="0.0"/>
  </inertial>
  <visual>
    <origin xyz="0.035 -0.0 -0.025" rpy="0 0 0"/>
    <geometry>
      <mesh filename="package://finalrobot2_1100452_description/meshes/left_wheel_1.stl" scale="0.001 0.001 0.001"/>
    </geometry>
    <material name="silver"/>
  </visual>
  <collision>
    <origin xyz="0.035 -0.0 -0.025" rpy="0 0 0"/>
    <geometry>
      <mesh filename="package://finalrobot2_1100452_description/meshes/left_wheel_1.stl" scale="0.001 0.001 0.001"/>
    </geometry>
  </collision>
</link>

<link name="lidar_1">
  <inertial>
    <origin xyz="5.228398398502882e-13 6.938893903907228e-18 0.015000000000000138" rpy="0 0 0"/>
    <mass value="0.018496126748009507"/>
    <inertia ixx="2e-06" iyy="2e-06" izz="0.0" ixy="0.0" iyz="0.0" ixz="0.0"/>
  </inertial>
  <visual>
    <origin xyz="-0.0 0.045 -0.0675" rpy="0 0 0"/>
    <geometry>
      <mesh filename="package://finalrobot2_1100452_description/meshes/lidar_1.stl" scale="0.001 0.001 0.001"/>
    </geometry>
    <material name="silver"/>
  </visual>
  <collision>
    <origin xyz="-0.0 0.045 -0.0675" rpy="0 0 0"/>
    <geometry>
      <mesh filename="package://finalrobot2_1100452_description/meshes/lidar_1.stl" scale="0.001 0.001 0.001"/>
    </geometry>
  </collision>
</link>

<joint name="Revolute 1" type="continuous">
  <origin xyz="0.03 0.0 0.025" rpy="0 0 0"/>
  <parent link="base_link"/>
  <child link="right_wheel_1"/>
  <axis xyz="0.0 -1.0 0.0"/>
</joint>

<joint name="Revolute 2" type="continuous">
  <origin xyz="-0.035 0.0 0.025" rpy="0 0 0"/>
  <parent link="base_link"/>
  <child link="left_wheel_1"/>
  <axis xyz="0.0 1.0 0.0"/>
</joint>

<joint name="Rigid 3" type="fixed">
  <origin xyz="0.0 -0.045 0.0675" rpy="0 0 0"/>
  <parent link="base_link"/>
  <child link="lidar_1"/>
</joint>

</robot>
